Workbook

Sheet Sheet1
A1: Mukilteo Bishops' Storehouse | D1: 46209
A2: Monthly Inventory Worksheet, Version 2 | C2: 1 | D2: month supply calculation | P2: Michael's POF
A3: Item number | B3: Product name | C3: Add this number to Michael's POF Tranfer Quantity and return to him 6 | D3: Soonest Use-by Date 1 | E3: Surplus | F3: F Wirtz Minimum (in cases) | G3: G Current Rack count (if below Wirtz #) 2 | H3: H Transfer quantity (pasted into Michael's POF area) 5 | I3: I Send to surplus 3 | J3: J Upcoming Humanitarian count 4 | K3: K G+H-(I+J) Net Stock | L3: Items Per case | M3: Items Per tier | N3: Storehouse Location Row Column Shelf | O3: Item number | P3: Product name | Q3: Transfer quantity
A4: 000213 | B4: Scooters | C4: =IF(AND($C$2*F4>K4,G4+H4+I4+J4<>0),$C$2*F4-K4,0) -> 0 | D4: 46356 | E4: =IF(OR(DATEDIF(TODAY(),D4,"M")=1,DATEDIF(TODAY(),D4,"M")=0),1,0) -> 0 | F4: 27 | G4: 0 | H4: =_xlfn.XLOOKUP("000213", Sheet1!$O$4:$O$115, Sheet1!$Q$4:$Q$115,0) -> 0 | K4: =G4+H4-(I4+J4) -> 0 | L4: 9 | M4: 6 | N4: 1,1,1 | O4: 000014 | P4: Black Beans | Q4: 17 | R4: =YEARfrac(=today,d4)
A5: 000223 | B5: Raisin Bran | C5: =IF(AND($C$2*F5>K5,G5+H5+I5+J5<>0),$C$2*F5-K5,0) -> 7 | D5: 46301 | E5: =IF(OR(DATEDIF(TODAY(),D5,"M")=1,DATEDIF(TODAY(),D5,"M")=0),1,0) -> 0 | F5: 27 | G5: 20 | H5: =_xlfn.XLOOKUP("000223", Sheet1!$O$4:$O$115, Sheet1!$Q$4:$Q$115,0) -> 0 | K5: =G5+H5-(I5+J5) -> 20 | L5: 10 | M5: 9 | N5: 1,1,1 | O5: 000019 | P5: Chicken Breast Pieces (canned) | Q5: 32 | R5: =IF(OR(DATEDIF(TODAY(),D11,"M")=1,DATEDIF(TODAY(),D11,"M"))=0,8,22)
A6: 000231 | B6: Oats, Rolled | C6: =IF(AND($C$2*F6>K6,G6+H6+I6+J6<>0),$C$2*F6-K6,0) -> 0 | D6: 46429 | E6: =IF(OR(DATEDIF(TODAY(),D6,"M")=1,DATEDIF(TODAY(),D6,"M")=0),1,0) -> 0 | F6: 9 | G6: 10 | H6: =_xlfn.XLOOKUP("000231", Sheet1!$O$4:$O$115, Sheet1!$Q$4:$Q$115,0) -> 0 | K6: =G6+H6-(I6+J6) -> 10 | L6: 16 | M6: 9 | N6: 1,2,1 | O6: 000024 | P6: Corn | Q6: 17
A7: 000366 | B7: Diapers #4 | C7: =IF(AND($C$2*F7>K7,G7+H7+I7+J7<>0),$C$2*F7-K7,0) -> 0 | F7: 10 | G7: 0 | H7: =_xlfn.XLOOKUP("000366", Sheet1!$O$4:$O$115, Sheet1!$Q$4:$Q$115,0) -> 0 | K7: =G7+H7-(I7+J7) -> 0 | L7: 4 | M7: 10 | N7: 1,2,1 | O7: 000035 | P7: Instant Potatoes 12/28oz | Q7: 12
A8: 000182 | B8: Baby Cereal- 8oz. | C8: =IF(AND($C$2*F8>K8,G8+H8+I8+J8<>0),$C$2*F8-K8,0) -> 2 | D8: 46260 | E8: =IF(OR(DATEDIF(TODAY(),D8,"M")=1,DATEDIF(TODAY(),D8,"M")=0),1,0) -> 1 | F8: 4 | G8: 10 | H8: =_xlfn.XLOOKUP("000182", Sheet1!$O$4:$O$115, Sheet1!$Q$4:$Q$115,0) -> 0 | I8: 8 | K8: =G8+H8-(I8+J8) -> 2 | L8: 6 | M8: 20 | N8: 1,2,2 | O8: 000037 | P8: Diced Tomatoes 401 | Q8: 20
A9: 000184 | B9: Baby Formula | C9: =IF(AND($C$2*F9>K9,G9+H9+I9+J9<>0),$C$2*F9-K9,0) -> 0 | D9: 46811 | E9: =IF(OR(DATEDIF(TODAY(),D9,"M")=1,DATEDIF(TODAY(),D9,"M")=0),1,0) -> 0 | F9: 4 | G9: 4 | H9: =_xlfn.XLOOKUP("000184", Sheet1!$O$4:$O$115, Sheet1!$Q$4:$Q$115,0) -> 6 | K9: =G9+H9-(I9+J9) -> 10 | L9: 6 | M9: 16 | N9: 1,2,2 | O9: 000039 | P9: Tomato Sauce | Q9: 17
A10: 000362 | B10: Diapers #1 | C10: =IF(AND($C$2*F10>K10,G10+H10+I10+J10<>0),$C$2*F10-K10,0) -> 0 | F10: 8 | G10: 19 | H10: =_xlfn.XLOOKUP("000362", Sheet1!$O$4:$O$115, Sheet1!$Q$4:$Q$115,0) -> 0 | K10: =G10+H10-(I10+J10) -> 19 | L10: 4 | M10: 13 | N10: 1,2,2 | O10: 000042 | P10: Soup, Chicken Flavored Rotini | Q10: 17
A11: 000365 | B11: Diapers #3 | C11: =IF(AND($C$2*F11>K11,G11+H11+I11+J11<>0),$C$2*F11-K11,0) -> 0 | F11: 8 | G11: 0 | H11: =_xlfn.XLOOKUP("000365", Sheet1!$O$4:$O$115, Sheet1!$Q$4:$Q$115,0) -> 0 | K11: =G11+H11-(I11+J11) -> 0 | L11: 4 | M11: 10 | N11: 1,2,2 | O11: 000056 | P11: Applesauce 26.5oz | Q11: 14
A12: 000370 | B12: Baby Wipes | C12: =IF(AND($C$2*F12>K12,G12+H12+I12+J12<>0),$C$2*F12-K12,0) -> 0 | F12: 16 | G12: 68 | H12: =_xlfn.XLOOKUP("000370", Sheet1!$O$4:$O$115, Sheet1!$Q$4:$Q$115,0) -> 0 | J12: 12 | K12: =G12+H12-(I12+J12) -> 56 | L12: 12 | M12: 15 | N12: 1,2,2 | O12: 000090 | P12: Spaghetti Sauce 26.5oz | Q12: 70
A13: 000345 | B13: Liquid Bleach Concentrate (New) | C13: =IF(AND($C$2*F13>K13,G13+H13+I13+J13<>0),$C$2*F13-K13,0) -> 0 | F13: 15 | G13: 31 | H13: =_xlfn.XLOOKUP("000345", Sheet1!$O$4:$O$115, Sheet1!$Q$4:$Q$115,0) -> 0 | K13: =G13+H13-(I13+J13) -> 31 | L13: 6 | M13: 15 | N13: 1,3,1 | O13: 000100 | P13: Evaporated Milk | Q13: 9
A14: 000351 | B14: Cleanser (Ajax or Comet) | C14: =IF(AND($C$2*F14>K14,G14+H14+I14+J14<>0),$C$2*F14-K14,0) -> 0 | F14: 5 | G14: 3 | H14: =_xlfn.XLOOKUP("000351", Sheet1!$O$4:$O$115, Sheet1!$Q$4:$Q$115,0) -> 8 | K14: =G14+H14-(I14+J14) -> 11 | L14: 24 | M14: 9 | N14: 1,3,1 | O14: 000102 | P14: Peanut Butter 16 oz (New) | Q14: 15
A15: 000369 | B15: Aluminum Foil | C15: =IF(AND($C$2*F15>K15,G15+H15+I15+J15<>0),$C$2*F15-K15,0) -> 0 | F15: 4 | G15: 10 | H15: =_xlfn.XLOOKUP("000369", Sheet1!$O$4:$O$115, Sheet1!$Q$4:$Q$115,0) -> 6 | K15: =G15+H15-(I15+J15) -> 16 | L15: 35 | M15: 17 | N15: 1,3,1 | O15: 000109 | P15: Baking Soda 12/12oz | Q15: 8
A16: 000390 | B16: Plastic Wrap | C16: =IF(AND($C$2*F16>K16,G16+H16+I16+J16<>0),$C$2*F16-K16,0) -> 0 | F16: 4 | G16: 9 | H16: =_xlfn.XLOOKUP("000390", Sheet1!$O$4:$O$115, Sheet1!$Q$4:$Q$115,0) -> 6 | K16: =G16+H16-(I16+J16) -> 15 | L16: 24 | M16: 16 | N16: 1,3,1 | O16: 000121 | P16: Pudding, Vanilla | Q16: 4
A17: 000354 | B17: Liquid Dish Soap | C17: =IF(AND($C$2*F17>K17,G17+H17+I17+J17<>0),$C$2*F17-K17,0) -> 0 | F17: 18 | G17: 74 | H17: =_xlfn.XLOOKUP("000354", Sheet1!$O$4:$O$115, Sheet1!$Q$4:$Q$115,0) -> 0 | K17: =G17+H17-(I17+J17) -> 74 | L17: 12 | M17: 17 | N17: 1,3,2 | O17: 000141 | P17: Black Pepper 12/ct | Q17: 8
A18: 000395 | B18: Razor | C18: =IF(AND($C$2*F18>K18,G18+H18+I18+J18<>0),$C$2*F18-K18,0) -> 0 | F18: 10 | G18: 15 | H18: =_xlfn.XLOOKUP("000395", Sheet1!$O$4:$O$115, Sheet1!$Q$4:$Q$115,0) -> 0 | K18: =G18+H18-(I18+J18) -> 15 | L18: 36 | M18: 18 | N18: 1,3,2 | O18: 000151 | P18: Mayo | Q18: 10
A19: 000420 | B19: Shaving Cream 10 oz. (New) | C19: =IF(AND($C$2*F19>K19,G19+H19+I19+J19<>0),$C$2*F19-K19,0) -> 0 | F19: 18 | G19: 21 | H19: =_xlfn.XLOOKUP("000420", Sheet1!$O$4:$O$115, Sheet1!$Q$4:$Q$115,0) -> 0 | K19: =G19+H19-(I19+J19) -> 21 | L19: 6 | M19: 45 | N19: 1,3,2 | O19: 000162 | P19: Sugar, Brown | Q19: 12
A20: 000350 | B20: Lysol Cleaner | C20: =IF(AND($C$2*F20>K20,G20+H20+I20+J20<>0),$C$2*F20-K20,0) -> 0 | F20: 10 | G20: 45 | H20: =_xlfn.XLOOKUP("000350", Sheet1!$O$4:$O$115, Sheet1!$Q$4:$Q$115,0) -> 0 | K20: =G20+H20-(I20+J20) -> 45 | L20: 12 | M20: 9 | N20: 1,4,1 | O20: 000172 | P20: Vanilla Flavor | Q20: 2
A21: 000357 | B21: Dishwasher Detergent (liquid) | C21: =IF(AND($C$2*F21>K21,G21+H21+I21+J21<>0),$C$2*F21-K21,0) -> 0 | F21: 18 | G21: 48 | H21: =_xlfn.XLOOKUP("000357", Sheet1!$O$4:$O$115, Sheet1!$Q$4:$Q$115,0) -> 0 | K21: =G21+H21-(I21+J21) -> 48 | L21: 10 | M21: 12 | N21: 1,4,1 | O21: 000178 | P21: Yeast | Q21: 1
A22: 000363 | B22: Shampoo | C22: =IF(AND($C$2*F22>K22,G22+H22+I22+J22<>0),$C$2*F22-K22,0) -> 0 | F22: 16 | G22: 6 | H22: =_xlfn.XLOOKUP("000363", Sheet1!$O$4:$O$115, Sheet1!$Q$4:$Q$115,0) -> 26 | K22: =G22+H22-(I22+J22) -> 32 | L22: 12 | M22: 26 | N22: 1,4,2 | O22: 000184 | P22: Baby Formula | Q22: 6
A23: 000371 | B23: Hand Soap | C23: =IF(AND($C$2*F23>K23,G23+H23+I23+J23<>0),$C$2*F23-K23,0) -> 5 | F23: 6 | G23: 1 | H23: =_xlfn.XLOOKUP("000371", Sheet1!$O$4:$O$115, Sheet1!$Q$4:$Q$115,0) -> 0 | K23: =G23+H23-(I23+J23) -> 1 | L23: 24 | M23: 21 | N23: 1,4,2 | O23: 000189 | P23: Refried Beans (Dehydrated) | Q23: 9
A24: 000415 | B24: Deodorant, Men | C24: =IF(AND($C$2*F24>K24,G24+H24+I24+J24<>0),$C$2*F24-K24,0) -> 0 | F24: 10 | G24: 12 | H24: =_xlfn.XLOOKUP("000415", Sheet1!$O$4:$O$115, Sheet1!$Q$4:$Q$115,0) -> 0 | K24: =G24+H24-(I24+J24) -> 12 | L24: 12 | M24: 40 | N24: 1,4,2 | O24: 000206 | P24: Pancake and waffle Mix | Q24: 18
A25: 000416 | B25: Deodorant Women | C25: =IF(AND($C$2*F25>K25,G25+H25+I25+J25<>0),$C$2*F25-K25,0) -> 0 | F25: 10 | G25: 21 | H25: =_xlfn.XLOOKUP("000416", Sheet1!$O$4:$O$115, Sheet1!$Q$4:$Q$115,0) -> 0 | K25: =G25+H25-(I25+J25) -> 21 | L25: 12 | M25: 42 | N25: 1,4,2 | O25: 000208 | P25: Cake Mix, Chocolate | Q25: 9
A26: 000421 | B26: Toothpaste | C26: =IF(AND($C$2*F26>K26,G26+H26+I26+J26<>0),$C$2*F26-K26,0) -> 0 | D26: 46752 | E26: =IF(OR(DATEDIF(TODAY(),D26,"M")=1,DATEDIF(TODAY(),D26,"M")=0),1,0) -> 0 | F26: 5 | G26: 6 | H26: =_xlfn.XLOOKUP("000421", Sheet1!$O$4:$O$115, Sheet1!$Q$4:$Q$115,0) -> 12 | K26: =G26+H26-(I26+J26) -> 18 | L26: 24 | M26: 12 | N26: 1,4,2 | O26: 000209 | P26: Cake Mix, Yellow | Q26: 9
A27: 000423 | B27: Toothbrush Adult | C27: =IF(AND($C$2*F27>K27,G27+H27+I27+J27<>0),$C$2*F27-K27,0) -> 0 | F27: 3 | G27: 5 | H27: =_xlfn.XLOOKUP("000423", Sheet1!$O$4:$O$115, Sheet1!$Q$4:$Q$115,0) -> 2 | K27: =G27+H27-(I27+J27) -> 7 | L27: 72 | M27: 20 | N27: 1,4,2 | O27: 000212 | P27: Flour, white 5lb | Q27: 36
A28: 000426 | B28: Toothbrush Child | C28: =IF(AND($C$2*F28>K28,G28+H28+I28+J28<>0),$C$2*F28-K28,0) -> 0 | F28: 6 | G28: 9 | H28: =_xlfn.XLOOKUP("000426", Sheet1!$O$4:$O$115, Sheet1!$Q$4:$Q$115,0) -> 0 | K28: =G28+H28-(I28+J28) -> 9 | L28: 36 | M28: 35 | N28: 1,4,2 | O28: 000234 | P28: Spaghetti | Q28: 12
A29: 000359 | B29: Laundry Detergent | C29: =IF(AND($C$2*F29>K29,G29+H29+I29+J29<>0),$C$2*F29-K29,0) -> 0 | F29: 27 | G29: 0 | H29: =_xlfn.XLOOKUP("000359", Sheet1!$O$4:$O$115, Sheet1!$Q$4:$Q$115,0) -> 48 | K29: =G29+H29-(I29+J29) -> 48 | L29: 6 | M29: 12 | N29: 1,5,1 | O29: 000255 | P29: Potatoes | Q29: 14
A30: 000399 | B30: Sanitary Pads | C30: =IF(AND($C$2*F30>K30,G30+H30+I30+J30<>0),$C$2*F30-K30,0) -> 0 | F30: 3 | G30: 64 | H30: =_xlfn.XLOOKUP("000399", Sheet1!$O$4:$O$115, Sheet1!$Q$4:$Q$115,0) -> 0 | J30: 31 | K30: =G30+H30-(I30+J30) -> 33 | L30: 12 | M30: 9 | N30: 1,5,1 | O30: 000267 | P30: Apples | Q30: 12
A31: 000406 | B31: Tampons -- Regular | C31: =IF(AND($C$2*F31>K31,G31+H31+I31+J31<>0),$C$2*F31-K31,0) -> 0 | F31: 5 | G31: 10 | H31: =_xlfn.XLOOKUP("000406", Sheet1!$O$4:$O$115, Sheet1!$Q$4:$Q$115,0) -> 0 | K31: =G31+H31-(I31+J31) -> 10 | L31: 6 | M31: 28 | N31: 1,5,2 | O31: 000289 | P31: Hot Cocoa | Q31: 12
A32: 000407 | B32: Tampons -- Super | C32: =IF(AND($C$2*F32>K32,G32+H32+I32+J32<>0),$C$2*F32-K32,0) -> 0 | F32: 5 | G32: 12 | H32: =_xlfn.XLOOKUP("000407", Sheet1!$O$4:$O$115, Sheet1!$Q$4:$Q$115,0) -> 0 | K32: =G32+H32-(I32+J32) -> 12 | L32: 6 | M32: 24 | N32: 1,5,2 | O32: 000292 | P32: Butter | Q32: 13
A33: 000419 | B33: Toilet Paper 4 pack | C33: =IF(AND($C$2*F33>K33,G33+H33+I33+J33<>0),$C$2*F33-K33,0) -> 44 | F33: 84 | G33: 0 | H33: =_xlfn.XLOOKUP("000419", Sheet1!$O$4:$O$115, Sheet1!$Q$4:$Q$115,0) -> 40 | K33: =G33+H33-(I33+J33) -> 40 | L33: 12 | M33: 8 | N33: 1,6,1 | O33: 000298 | P33: Cheese | Q33: 12
A34: 000206 | B34: Pancake Mix | C34: =IF(AND($C$2*F34>K34,G34+H34+I34+J34<>0),$C$2*F34-K34,0) -> 0 | D34: 46569 | E34: =IF(OR(DATEDIF(TODAY(),D34,"M")=1,DATEDIF(TODAY(),D34,"M")=0),1,0) -> 0 | F34: 9 | G34: 15 | H34: =_xlfn.XLOOKUP("000206", Sheet1!$O$4:$O$115, Sheet1!$Q$4:$Q$115,0) -> 18 | K34: =G34+H34-(I34+J34) -> 33 | L34: 8 | M34: 9 | N34: 2,1,1 | O34: 000305 | P34: Beef Ground | Q34: 20
A35: 000234 | B35: Spaghetti | C35: =IF(AND($C$2*F35>K35,G35+H35+I35+J35<>0),$C$2*F35-K35,0) -> 0 | D35: 47001 | E35: =IF(OR(DATEDIF(TODAY(),D35,"M")=1,DATEDIF(TODAY(),D35,"M")=0),1,0) -> 0 | F35: 5 | G35: 0 | H35: =_xlfn.XLOOKUP("000234", Sheet1!$O$4:$O$115, Sheet1!$Q$4:$Q$115,0) -> 12 | K35: =G35+H35-(I35+J35) -> 12 | L35: 24 | M35: 12 | N35: 2,1,1 | O35: 000310 | P35: Beef Stewing | Q35: 10
A36: 000222 | B36: Macaroni & Cheese | C36: =IF(AND($C$2*F36>K36,G36+H36+I36+J36<>0),$C$2*F36-K36,0) -> 0 | D36: 47139 | E36: =IF(OR(DATEDIF(TODAY(),D36,"M")=1,DATEDIF(TODAY(),D36,"M")=0),1,0) -> 0 | F36: 5 | G36: 81 | H36: =_xlfn.XLOOKUP("000222", Sheet1!$O$4:$O$115, Sheet1!$Q$4:$Q$115,0) -> 0 | J36: 43 | K36: =G36+H36-(I36+J36) -> 38 | L36: 48 | M36: 10 | N36: 2,1,2 | O36: 000313 | P36: Beef Roast | Q36: 20
A37: 000226 | B37: Ribbon Pasta | C37: =IF(AND($C$2*F37>K37,G37+H37+I37+J37<>0),$C$2*F37-K37,0) -> 0 | D37: 46935 | E37: =IF(OR(DATEDIF(TODAY(),D37,"M")=1,DATEDIF(TODAY(),D37,"M")=0),1,0) -> 0 | F37: 7 | G37: 17 | H37: =_xlfn.XLOOKUP("000226", Sheet1!$O$4:$O$115, Sheet1!$Q$4:$Q$115,0) -> 0 | K37: =G37+H37-(I37+J37) -> 17 | L37: 24 | M37: 7 | N37: 2,1,2 | O37: 000320 | P37: Ham | Q37: 10
A38: 000167 | B38: Sugar | C38: =IF(AND($C$2*F38>K38,G38+H38+I38+J38<>0),$C$2*F38-K38,0) -> 0 | D38: 47307 | E38: =IF(OR(DATEDIF(TODAY(),D38,"M")=1,DATEDIF(TODAY(),D38,"M")=0),1,0) -> 0 | F38: 10 | G38: 0 | H38: =_xlfn.XLOOKUP("000167", Sheet1!$O$4:$O$115, Sheet1!$Q$4:$Q$115,0) -> 0 | K38: =G38+H38-(I38+J38) -> 0 | L38: 10 | M38: 10 | N38: 2,2,1 | O38: 000325 | P38: Pork Roast- 10 Count | Q38: 10
A39: 000211 | B39: White Flour | C39: =IF(AND($C$2*F39>K39,G39+H39+I39+J39<>0),$C$2*F39-K39,0) -> 0 | D39: 46664 | E39: =IF(OR(DATEDIF(TODAY(),D39,"M")=1,DATEDIF(TODAY(),D39,"M")=0),1,0) -> 0 | F39: 9 | G39: 0 | H39: =_xlfn.XLOOKUP("000211", Sheet1!$O$4:$O$115, Sheet1!$Q$4:$Q$115,0) -> 0 | K39: =G39+H39-(I39+J39) -> 0 | L39: 4 | M39: 9 | N39: 2,2,1 | O39: 000331 | P39: IQF Chicken Breast | Q39: 30
A40: 000212 | B40: White Flour 5lb | C40: =IF(AND($C$2*F40>K40,G40+H40+I40+J40<>0),$C$2*F40-K40,0) -> 0 | F40: 9 | G40: 36 | H40: =_xlfn.XLOOKUP("000212", Sheet1!$O$4:$O$115, Sheet1!$Q$4:$Q$115,0) -> 36 | K40: =G40+H40-(I40+J40) -> 72 | L40: 4 | M40: 10 | N40: 2,2,1 | O40: 000343 | P40: Beef Franks | Q40: 10
...
